<sdf version='1.7'>
  <world name='default'>
    <light name='sun' type='directional'>
      <cast_shadows>1</cast_shadows>
      <pose>0 0 10 0 -0 0</pose>
      <diffuse>0.8 0.8 0.8 1</diffuse>
      <specular>0.2 0.2 0.2 1</specular>
      <attenuation>
        <range>1000</range>
        <constant>0.9</constant>
        <linear>0.01</linear>
        <quadratic>0.001</quadratic>
      </attenuation>
      <direction>-0.5 0.1 -0.9</direction>
      <spot>
        <inner_angle>0</inner_angle>
        <outer_angle>0</outer_angle>
        <falloff>0</falloff>
      </spot>
    </light>
    <model name='ground_plane'>
      <static>1</static>
      <link name='link'>
        <collision name='collision'>
          <geometry>
            <plane>
              <normal>0 0 1</normal>
              <size>100 100</size>
            </plane>
          </geometry>
          <surface>
            <contact>
              <collide_bitmask>65535</collide_bitmask>
              <ode/>
            </contact>
            <friction>
              <ode>
                <mu>100</mu>
                <mu2>50</mu2>
              </ode>
              <torsional>
                <ode/>
              </torsional>
            </friction>
            <bounce/>
          </surface>
          <max_contacts>10</max_contacts>
        </collision>
        <visual name='visual'>
          <cast_shadows>0</cast_shadows>
          <geometry>
            <plane>
              <normal>0 0 1</normal>
              <size>100 100</size>
            </plane>
          </geometry>
          <material>
            <script>
              <uri>file://media/materials/scripts/gazebo.material</uri>
              <name>Gazebo/Grey</name>
            </script>
          </material>
        </visual>
        <self_collide>0</self_collide>
        <enable_wind>0</enable_wind>
        <kinematic>0</kinematic>
      </link>
    </model>
    <gravity>0 0 -9.8</gravity>
    <magnetic_field>6e-06 2.3e-05 -4.2e-05</magnetic_field>
    <atmosphere type='adiabatic'/>
    <physics type='ode'>
      <max_step_size>0.001</max_step_size>
      <real_time_factor>1</real_time_factor>
      <real_time_update_rate>1000</real_time_update_rate>
    </physics>
    <scene>
      <ambient>0.4 0.4 0.4 1</ambient>
      <background>0.7 0.7 0.7 1</background>
      <shadows>1</shadows>
    </scene>
    <wind/>
    <spherical_coordinates>
      <surface_model>EARTH_WGS84</surface_model>
      <latitude_deg>0</latitude_deg>
      <longitude_deg>0</longitude_deg>
      <elevation>0</elevation>
      <heading_deg>0</heading_deg>
    </spherical_coordinates>
    <model name='basic_mobile_bot'>
      <static>0</static>
      <pose>0.291666 1.60957 0 0 -0 0</pose>
      <link name='base_footprint'>
        <self_collide>0</self_collide>
        <inertial>
          <pose>0 0 0 0 -0 0</pose>
          <inertia>
            <ixx>1</ixx>
            <ixy>0</ixy>
            <ixz>0</ixz>
            <iyy>1</iyy>
            <iyz>0</iyz>
            <izz>1</izz>
          </inertia>
          <mass>1</mass>
        </inertial>
        <enable_wind>0</enable_wind>
        <kinematic>0</kinematic>
      </link>
      <link name='base_link'>
        <collision name='base_collision'>
          <pose>0 0 0.1 0 -0 0</pose>
          <geometry>
            <box>
              <size>0.7 0.39 0.2</size>
            </box>
          </geometry>
          <max_contacts>10</max_contacts>
          <surface>
            <contact>
              <ode/>
            </contact>
            <bounce/>
            <friction>
              <torsional>
                <ode/>
              </torsional>
              <ode/>
            </friction>
          </surface>
        </collision>
        <visual name='base_visual'>
          <pose>0 0 -0.05 1.5708 -0 -3.14159</pose>
          <geometry>
            <mesh>
              <uri>model://basic_mobile_bot_description/meshes/robot_base.stl</uri>
              <scale>1 1 1</scale>
            </mesh>
          </geometry>
          <material>
            <ambient>1 0 0 1</ambient>
            <diffuse>1 0 0 1</diffuse>
            <specular>0 0 0 1</specular>
            <emissive>0 0 0 1</emissive>
          </material>
        </visual>
        <self_collide>0</self_collide>
        <inertial>
          <pose>0 0 0 0 -0 0</pose>
          <inertia>
            <ixx>1</ixx>
            <ixy>0</ixy>
            <ixz>0</ixz>
            <iyy>1</iyy>
            <iyz>0</iyz>
            <izz>1</izz>
          </inertia>
          <mass>1</mass>
        </inertial>
        <enable_wind>0</enable_wind>
        <kinematic>0</kinematic>
      </link>
      <link name='imu_link'>
        <gravity>1</gravity>
        <sensor name='bmb_imu' type='imu'>
          <always_on>1</always_on>
          <update_rate>100</update_rate>
          <visualize>1</visualize>
          <imu>
            <angular_velocity>
              <x>
                <noise type='gaussian'>
                  <mean>0</mean>
                  <stddev>0.0002</stddev>
                </noise>
              </x>
              <y>
                <noise type='gaussian'>
                  <mean>0</mean>
                  <stddev>0.0002</stddev>
                </noise>
              </y>
              <z>
                <noise type='gaussian'>
                  <mean>0</mean>
                  <stddev>0.0002</stddev>
                </noise>
              </z>
            </angular_velocity>
            <linear_acceleration>
              <x>
                <noise type='gaussian'>
                  <mean>0</mean>
                  <stddev>0.017</stddev>
                </noise>
              </x>
              <y>
                <noise type='gaussian'>
                  <mean>0</mean>
                  <stddev>0.017</stddev>
                </noise>
              </y>
              <z>
                <noise type='gaussian'>
                  <mean>0</mean>
                  <stddev>0.017</stddev>
                </noise>
              </z>
            </linear_acceleration>
            <angular_velocity/>
            <linear_acceleration/>
            <orientation>
              <x>
                <noise type='gaussian'>
                  <mean>0.0</mean>
                  <stddev>2e-3</stddev>
                </noise>
              </x>
              <y>
                <noise type='gaussian'>
                  <mean>0.0</mean>
                  <stddev>2e-3</stddev>
                </noise>
              </y>
              <z>
                <noise type='gaussian'>
                  <mean>0.0</mean>
                  <stddev>2e-3</stddev>
                </noise>
              </z>
            </orientation>
          </imu>
          <plugin name='basic_mobile_bot_imu' filename='libgazebo_ros_imu_sensor.so'>
            <initial_orientation_as_reference>0</initial_orientation_as_reference>
            <frame_name>imu_link</frame_name>
            <ros>
              <namespace>/imu</namespace>
              <remapping>~/out:=data</remapping>
            </ros>
          </plugin>
        </sensor>
        <self_collide>0</self_collide>
        <inertial>
          <pose>0 0 0 0 -0 0</pose>
          <inertia>
            <ixx>1</ixx>
            <ixy>0</ixy>
            <ixz>0</ixz>
            <iyy>1</iyy>
            <iyz>0</iyz>
            <izz>1</izz>
          </inertia>
          <mass>1</mass>
        </inertial>
        <enable_wind>0</enable_wind>
        <kinematic>0</kinematic>
      </link>
      <link name='gps_link'>
        <sensor name='bmb_gps' type='gps'>
          <always_on>1</always_on>
          <update_rate>10</update_rate>
          <gps>
            <position_sensing>
              <horizontal>
                <noise type='gaussian'>
                  <mean>0</mean>
                  <stddev>0.01</stddev>
                </noise>
              </horizontal>
              <vertical>
                <noise type='gaussian'>
                  <mean>0</mean>
                  <stddev>1</stddev>
                </noise>
              </vertical>
            </position_sensing>
          </gps>
          <plugin name='basic_mobile_bot_gps' filename='libgazebo_ros_gps_sensor.so'>
            <ros>
              <remapping>~/out:=gps/fix</remapping>
            </ros>
          </plugin>
        </sensor>
        <self_collide>0</self_collide>
        <inertial>
          <pose>0 0 0 0 -0 0</pose>
          <inertia>
            <ixx>1</ixx>
            <ixy>0</ixy>
            <ixz>0</ixz>
            <iyy>1</iyy>
            <iyz>0</iyz>
            <izz>1</izz>
          </inertia>
          <mass>1</mass>
        </inertial>
        <enable_wind>0</enable_wind>
        <kinematic>0</kinematic>
      </link>
      <link name='drivewhl_l_link'>
        <pose>-0.221 0.23 -0.05 3.14159 1.57079 -1.57079</pose>
        <collision name='drivewhl_l_collision'>
          <geometry>
            <cylinder>
              <radius>0.14</radius>
              <length>0.06</length>
            </cylinder>
          </geometry>
          <max_contacts>10</max_contacts>
          <surface>
            <contact>
              <ode/>
            </contact>
            <bounce/>
            <friction>
              <torsional>
                <ode/>
              </torsional>
              <ode/>
            </friction>
          </surface>
        </collision>
        <visual name='drivewhl_l_visual'>
          <geometry>
            <cylinder>
              <radius>0.14</radius>
              <length>0.06</length>
            </cylinder>
          </geometry>
        </visual>
        <self_collide>0</self_collide>
        <inertial>
          <pose>0 0 0 0 -0 0</pose>
          <inertia>
            <ixx>1</ixx>
            <ixy>0</ixy>
            <ixz>0</ixz>
            <iyy>1</iyy>
            <iyz>0</iyz>
            <izz>1</izz>
          </inertia>
          <mass>1</mass>
        </inertial>
        <enable_wind>0</enable_wind>
        <kinematic>0</kinematic>
      </link>
      <link name='drivewhl_r_link'>
        <pose>-0.221 -0.23 -0.05 3.14159 1.57079 -1.57079</pose>
        <collision name='drivewhl_r_collision'>
          <geometry>
            <cylinder>
              <radius>0.14</radius>
              <length>0.06</length>
            </cylinder>
          </geometry>
          <max_contacts>10</max_contacts>
          <surface>
            <contact>
              <ode/>
            </contact>
            <bounce/>
            <friction>
              <torsional>
                <ode/>
              </torsional>
              <ode/>
            </friction>
          </surface>
        </collision>
        <visual name='drivewhl_r_visual'>
          <geometry>
            <cylinder>
              <radius>0.14</radius>
              <length>0.06</length>
            </cylinder>
          </geometry>
        </visual>
        <self_collide>0</self_collide>
        <inertial>
          <pose>0 0 0 0 -0 0</pose>
          <inertia>
            <ixx>1</ixx>
            <ixy>0</ixy>
            <ixz>0</ixz>
            <iyy>1</iyy>
            <iyz>0</iyz>
            <izz>1</izz>
          </inertia>
          <mass>1</mass>
        </inertial>
        <enable_wind>0</enable_wind>
        <kinematic>0</kinematic>
      </link>
      <link name='front_caster'>
        <pose>0.217 0 -0.1 0 -0 0</pose>
        <collision name='collision'>
          <geometry>
            <sphere>
              <radius>0.09</radius>
            </sphere>
          </geometry>
          <surface>
            <friction>
              <ode>
                <mu>0.01</mu>
                <mu2>0.01</mu2>
                <slip1>1</slip1>
                <slip2>1</slip2>
              </ode>
              <torsional>
                <ode/>
              </torsional>
            </friction>
            <contact>
              <ode/>
            </contact>
            <bounce/>
          </surface>
          <max_contacts>10</max_contacts>
        </collision>
        <visual name='front_caster_visual'>
          <geometry>
            <sphere>
              <radius>0.09</radius>
            </sphere>
          </geometry>
        </visual>
        <self_collide>0</self_collide>
        <inertial>
          <pose>0 0 0 0 -0 0</pose>
          <inertia>
            <ixx>1</ixx>
            <ixy>0</ixy>
            <ixz>0</ixz>
            <iyy>1</iyy>
            <iyz>0</iyz>
            <izz>1</izz>
          </inertia>
          <mass>1</mass>
        </inertial>
        <enable_wind>0</enable_wind>
        <kinematic>0</kinematic>
      </link>
      <joint name='base_joint' type='fixed'>
        <parent>base_footprint</parent>
        <child>base_link</child>
        <pose>0 0 0 0 -0 0</pose>
      </joint>
      <joint name='drivewhl_l_joint' type='revolute'>
        <parent>base_link</parent>
        <child>drivewhl_l_link</child>
        <pose>0 0 0 0 -0 0</pose>
        <axis>
          <xyz>0 0 1</xyz>
          <limit>
            <lower>-1e+16</lower>
            <upper>1e+16</upper>
          </limit>
          <dynamics>
            <spring_reference>0</spring_reference>
            <spring_stiffness>0</spring_stiffness>
          </dynamics>
        </axis>
      </joint>
      <joint name='drivewhl_r_joint' type='revolute'>
        <parent>base_link</parent>
        <child>drivewhl_r_link</child>
        <pose>0 0 0 0 -0 0</pose>
        <axis>
          <xyz>0 0 1</xyz>
          <limit>
            <lower>-1e+16</lower>
            <upper>1e+16</upper>
          </limit>
          <dynamics>
            <spring_reference>0</spring_reference>
            <spring_stiffness>0</spring_stiffness>
          </dynamics>
        </axis>
      </joint>
      <joint name='caster_joint' type='fixed'>
        <parent>base_link</parent>
        <child>front_caster</child>
        <pose>0 0 0 0 -0 0</pose>
      </joint>
      <joint name='imu_joint' type='fixed'>
        <parent>base_link</parent>
        <child>imu_link</child>
        <pose>0 0 0 0 -0 0</pose>
      </joint>
      <joint name='gps_joint' type='fixed'>
        <parent>base_link</parent>
        <child>gps_link</child>
        <pose>0 0 0 0 -0 0</pose>
      </joint>
      <plugin name='basic_mobile_bot_diff_drive' filename='libgazebo_ros_diff_drive.so'>
        <update_rate>30</update_rate>
        <left_joint>drivewhl_l_joint</left_joint>
        <right_joint>drivewhl_r_joint</right_joint>
        <wheel_separation>0.52</wheel_separation>
        <wheel_diameter>0.28</wheel_diameter>
        <max_wheel_torque>20</max_wheel_torque>
        <max_wheel_acceleration>1.0</max_wheel_acceleration>
        <command_topic>cmd_vel</command_topic>
        <publish_odom>1</publish_odom>
        <publish_odom_tf>0</publish_odom_tf>
        <publish_wheel_tf>0</publish_wheel_tf>
        <odometry_topic>odom</odometry_topic>
        <odometry_frame>odom</odometry_frame>
        <robot_base_frame>base_footprint</robot_base_frame>
        <odometry_source>0</odometry_source>
        <ros>
          <remapping>odom:=wheel/odometry</remapping>
        </ros>
      </plugin>
      <plugin name='basic_mobile_bot_joint_state' filename='libgazebo_ros_joint_state_publisher.so'>
        <ros>
          <remapping>~/out:=joint_states</remapping>
        </ros>
        <update_rate>30</update_rate>
        <joint_name>drivewhl_l_joint</joint_name>
        <joint_name>drivewhl_r_joint</joint_name>
      </plugin>
    </model>
    <state world_name='default'>
      <sim_time>26 196000000</sim_time>
      <real_time>26 588188971</real_time>
      <wall_time>1721678270 42387406</wall_time>
      <iterations>26196</iterations>
      <model name='basic_mobile_bot'>
        <pose>0.29553 1.61098 0.190001 -2e-06 -1e-06 0.005261</pose>
        <scale>1 1 1</scale>
        <link name='base_footprint'>
          <pose>0.29553 1.61098 0.190001 -2e-06 -1e-06 0.005261</pose>
          <velocity>-5.3e-05 -0.000258 0.000646 0.001699 -0.000221 0.000128</velocity>
          <acceleration>-0.398938 -0.395644 1.28092 -0.77304 0.984281 -2.98486</acceleration>
          <wrench>-0.398938 -0.395644 1.28092 0 -0 0</wrench>
        </link>
        <link name='base_link'>
          <pose>0.29553 1.61098 0.190001 -2e-06 -1e-06 0.005261</pose>
          <velocity>-5.4e-05 -0.000256 0.000627 0.001693 -0.00022 0.000128</velocity>
          <acceleration>-0.400662 -0.393403 1.26316 -0.781584 0.98574 -2.9848</acceleration>
          <wrench>-0.400662 -0.393403 1.26316 0 -0 0</wrench>
        </link>
        <link name='drivewhl_l_link'>
          <pose>0.073324 1.83981 0.14 -1.57306 1.56703 0.00301</pose>
          <velocity>-3.2e-05 -0.000241 0.001158 0.001723 -0.000226 0.000126</velocity>
          <acceleration>-0.496998 -0.360885 2.51335 -0.739246 0.991654 -2.98608</acceleration>
          <wrench>-0.496998 -0.360885 2.51335 0 -0 0</wrench>
        </link>
        <link name='drivewhl_r_link'>
          <pose>0.075743 1.37982 0.140001 -1.5729 1.56667 0.003168</pose>
          <velocity>-3.3e-05 -0.000184 -1.4e-05 0.001632 -0.000293 0.000128</velocity>
          <acceleration>-0.48912 -0.294657 0.922071 -0.848625 1.05898 -2.9847</acceleration>
          <wrench>-0.48912 -0.294657 0.922071 0 -0 0</wrench>
        </link>
        <link name='front_caster'>
          <pose>0.512527 1.61212 0.090001 -2e-06 -1e-06 0.005261</pose>
          <velocity>-3.4e-05 -5.7e-05 0.000734 0.00167 -0.000236 0.000129</velocity>
          <acceleration>-0.618912 -0.121676 0.734494 -0.812093 1.00009 -2.9841</acceleration>
          <wrench>-0.618912 -0.121676 0.734494 0 -0 0</wrench>
        </link>
        <link name='gps_link'>
          <pose>0.29553 1.61098 0.190001 -2e-06 -1e-06 0.005261</pose>
          <velocity>-6.2e-05 -0.000248 0.000608 0.001654 -0.000253 0.000129</velocity>
          <acceleration>-0.411008 -0.38284 1.16592 -0.833265 1.01372 -2.98352</acceleration>
          <wrench>-0.411008 -0.38284 1.16592 0 -0 0</wrench>
        </link>
        <link name='imu_link'>
          <pose>0.29553 1.61098 0.19 -2e-06 -1e-06 0.005261</pose>
          <velocity>-6.6e-05 -0.000243 0.000537 0.001638 -0.000261 0.00013</velocity>
          <acceleration>-0.416451 -0.377804 1.09405 -0.855024 1.02649 -2.98323</acceleration>
          <wrench>-0.416451 -0.377804 1.09405 0 -0 0</wrench>
        </link>
      </model>
      <model name='ground_plane'>
        <pose>0 0 0 0 -0 0</pose>
        <scale>1 1 1</scale>
        <link name='link'>
          <pose>0 0 0 0 -0 0</pose>
          <velocity>0 0 0 0 -0 0</velocity>
          <acceleration>0 0 0 0 -0 0</acceleration>
          <wrench>0 0 0 0 -0 0</wrench>
        </link>
      </model>
      <light name='sun'>
        <pose>0 0 10 0 -0 0</pose>
      </light>
    </state>
    <gui fullscreen='0'>
      <camera name='user_camera'>
        <pose>5.00529 -5.00529 1.97357 0 0.275643 2.35619</pose>
        <view_controller>orbit</view_controller>
        <projection_type>perspective</projection_type>
      </camera>
    </gui>
  </world>
</sdf>
